ERROR 2017-02-08 10:18:03,424 views 6411 140350626912000 ÈÇÆ‰ª∂ÂèëÈÄÅÂ§±Ë¥•: (535, b'5.7.8 authentication failed')
ERROR 2017-07-14 16:08:29,687 exception 13108 15280 Internal Server Error: /article/1
Traceback (most recent call last):
  File "E:\djangoproject\virblog\virblog\lib\site-packages\django_redis\cache.py", line 34, in _decorator
    return method(self, *args, **kwargs)
  File "E:\djangoproject\virblog\virblog\lib\site-packages\django_redis\cache.py", line 83, in get
    client=client)
  File "E:\djangoproject\virblog\virblog\lib\site-packages\django_redis\client\default.py", line 209, in get
    raise ConnectionInterrupted(connection=client, parent=e)
django_redis.exceptions.ConnectionInterrupted: Redis ConnectionError: Error 10061 connecting to 127.0.0.1:6379. ”…”⁄ƒø±Íº∆À„ª˙ª˝º´æ‹æ¯£¨Œﬁ∑®¡¨Ω”°£.

During handling of the above exception, another exception occurred:

Traceback (most recent call last):
  File "E:\djangoproject\virblog\virblog\lib\site-packages\django\core\handlers\exception.py", line 39, in inner
    response = get_response(request)
  File "E:\djangoproject\virblog\virblog\lib\site-packages\django\core\handlers\base.py", line 187, in _get_response
    response = self.process_exception_by_middleware(e, request)
  File "E:\djangoproject\virblog\virblog\lib\site-packages\django\core\handlers\base.py", line 185, in _get_response
    response = wrapped_callback(request, *callback_args, **callback_kwargs)
  File "E:\djangoproject\virblog\virblog\lib\site-packages\django\utils\decorators.py", line 141, in _wrapped_view
    result = middleware.process_request(request)
  File "E:\djangoproject\virblog\virblog\lib\site-packages\django\middleware\cache.py", line 133, in process_request
    cache_key = get_cache_key(request, self.key_prefix, 'GET', cache=self.cache)
  File "E:\djangoproject\virblog\virblog\lib\site-packages\django\utils\cache.py", line 318, in get_cache_key
    headerlist = cache.get(cache_key)
  File "E:\djangoproject\virblog\virblog\lib\site-packages\django_redis\cache.py", line 41, in _decorator
    raise e.parent
  File "E:\djangoproject\virblog\virblog\lib\site-packages\django_redis\client\default.py", line 207, in get
    value = client.get(key)
  File "E:\djangoproject\virblog\virblog\lib\site-packages\redis\client.py", line 880, in get
    return self.execute_command('GET', name)
  File "E:\djangoproject\virblog\virblog\lib\site-packages\redis\client.py", line 578, in execute_command
    connection.send_command(*args)
  File "E:\djangoproject\virblog\virblog\lib\site-packages\redis\connection.py", line 563, in send_command
    self.send_packed_command(self.pack_command(*args))
  File "E:\djangoproject\virblog\virblog\lib\site-packages\redis\connection.py", line 538, in send_packed_command
    self.connect()
  File "E:\djangoproject\virblog\virblog\lib\site-packages\redis\connection.py", line 442, in connect
    raise ConnectionError(self._error_message(e))
redis.exceptions.ConnectionError: Error 10061 connecting to 127.0.0.1:6379. ”…”⁄ƒø±Íº∆À„ª˙ª˝º´æ‹æ¯£¨Œﬁ∑®¡¨Ω”°£.
ERROR 2017-07-14 16:08:30,967 exception 13108 840 Internal Server Error: /article/1
Traceback (most recent call last):
  File "E:\djangoproject\virblog\virblog\lib\site-packages\django_redis\cache.py", line 34, in _decorator
    return method(self, *args, **kwargs)
  File "E:\djangoproject\virblog\virblog\lib\site-packages\django_redis\cache.py", line 83, in get
    client=client)
  File "E:\djangoproject\virblog\virblog\lib\site-packages\django_redis\client\default.py", line 209, in get
    raise ConnectionInterrupted(connection=client, parent=e)
django_redis.exceptions.ConnectionInterrupted: Redis ConnectionError: Error 10061 connecting to 127.0.0.1:6379. ”…”⁄ƒø±Íº∆À„ª˙ª˝º´æ‹æ¯£¨Œﬁ∑®¡¨Ω”°£.

During handling of the above exception, another exception occurred:

Traceback (most recent call last):
  File "E:\djangoproject\virblog\virblog\lib\site-packages\django\core\handlers\exception.py", line 39, in inner
    response = get_response(request)
  File "E:\djangoproject\virblog\virblog\lib\site-packages\django\core\handlers\base.py", line 187, in _get_response
    response = self.process_exception_by_middleware(e, request)
  File "E:\djangoproject\virblog\virblog\lib\site-packages\django\core\handlers\base.py", line 185, in _get_response
    response = wrapped_callback(request, *callback_args, **callback_kwargs)
  File "E:\djangoproject\virblog\virblog\lib\site-packages\django\utils\decorators.py", line 141, in _wrapped_view
    result = middleware.process_request(request)
  File "E:\djangoproject\virblog\virblog\lib\site-packages\django\middleware\cache.py", line 133, in process_request
    cache_key = get_cache_key(request, self.key_prefix, 'GET', cache=self.cache)
  File "E:\djangoproject\virblog\virblog\lib\site-packages\django\utils\cache.py", line 318, in get_cache_key
    headerlist = cache.get(cache_key)
  File "E:\djangoproject\virblog\virblog\lib\site-packages\django_redis\cache.py", line 41, in _decorator
    raise e.parent
  File "E:\djangoproject\virblog\virblog\lib\site-packages\django_redis\client\default.py", line 207, in get
    value = client.get(key)
  File "E:\djangoproject\virblog\virblog\lib\site-packages\redis\client.py", line 880, in get
    return self.execute_command('GET', name)
  File "E:\djangoproject\virblog\virblog\lib\site-packages\redis\client.py", line 578, in execute_command
    connection.send_command(*args)
  File "E:\djangoproject\virblog\virblog\lib\site-packages\redis\connection.py", line 563, in send_command
    self.send_packed_command(self.pack_command(*args))
  File "E:\djangoproject\virblog\virblog\lib\site-packages\redis\connection.py", line 538, in send_packed_command
    self.connect()
  File "E:\djangoproject\virblog\virblog\lib\site-packages\redis\connection.py", line 442, in connect
    raise ConnectionError(self._error_message(e))
redis.exceptions.ConnectionError: Error 10061 connecting to 127.0.0.1:6379. ”…”⁄ƒø±Íº∆À„ª˙ª˝º´æ‹æ¯£¨Œﬁ∑®¡¨Ω”°£.
ERROR 2017-07-14 16:08:32,885 exception 13108 4528 Internal Server Error: /article/1
Traceback (most recent call last):
  File "E:\djangoproject\virblog\virblog\lib\site-packages\django_redis\cache.py", line 34, in _decorator
    return method(self, *args, **kwargs)
  File "E:\djangoproject\virblog\virblog\lib\site-packages\django_redis\cache.py", line 83, in get
    client=client)
  File "E:\djangoproject\virblog\virblog\lib\site-packages\django_redis\client\default.py", line 209, in get
    raise ConnectionInterrupted(connection=client, parent=e)
django_redis.exceptions.ConnectionInterrupted: Redis ConnectionError: Error 10061 connecting to 127.0.0.1:6379. ”…”⁄ƒø±Íº∆À„ª˙ª˝º´æ‹æ¯£¨Œﬁ∑®¡¨Ω”°£.

During handling of the above exception, another exception occurred:

Traceback (most recent call last):
  File "E:\djangoproject\virblog\virblog\lib\site-packages\django\core\handlers\exception.py", line 39, in inner
    response = get_response(request)
  File "E:\djangoproject\virblog\virblog\lib\site-packages\django\core\handlers\base.py", line 187, in _get_response
    response = self.process_exception_by_middleware(e, request)
  File "E:\djangoproject\virblog\virblog\lib\site-packages\django\core\handlers\base.py", line 185, in _get_response
    response = wrapped_callback(request, *callback_args, **callback_kwargs)
  File "E:\djangoproject\virblog\virblog\lib\site-packages\django\utils\decorators.py", line 141, in _wrapped_view
    result = middleware.process_request(request)
  File "E:\djangoproject\virblog\virblog\lib\site-packages\django\middleware\cache.py", line 133, in process_request
    cache_key = get_cache_key(request, self.key_prefix, 'GET', cache=self.cache)
  File "E:\djangoproject\virblog\virblog\lib\site-packages\django\utils\cache.py", line 318, in get_cache_key
    headerlist = cache.get(cache_key)
  File "E:\djangoproject\virblog\virblog\lib\site-packages\django_redis\cache.py", line 41, in _decorator
    raise e.parent
  File "E:\djangoproject\virblog\virblog\lib\site-packages\django_redis\client\default.py", line 207, in get
    value = client.get(key)
  File "E:\djangoproject\virblog\virblog\lib\site-packages\redis\client.py", line 880, in get
    return self.execute_command('GET', name)
  File "E:\djangoproject\virblog\virblog\lib\site-packages\redis\client.py", line 578, in execute_command
    connection.send_command(*args)
  File "E:\djangoproject\virblog\virblog\lib\site-packages\redis\connection.py", line 563, in send_command
    self.send_packed_command(self.pack_command(*args))
  File "E:\djangoproject\virblog\virblog\lib\site-packages\redis\connection.py", line 538, in send_packed_command
    self.connect()
  File "E:\djangoproject\virblog\virblog\lib\site-packages\redis\connection.py", line 442, in connect
    raise ConnectionError(self._error_message(e))
redis.exceptions.ConnectionError: Error 10061 connecting to 127.0.0.1:6379. ”…”⁄ƒø±Íº∆À„ª˙ª˝º´æ‹æ¯£¨Œﬁ∑®¡¨Ω”°£.
ERROR 2017-07-14 16:08:33,391 exception 13108 2524 Internal Server Error: /article/1
Traceback (most recent call last):
  File "E:\djangoproject\virblog\virblog\lib\site-packages\django_redis\cache.py", line 34, in _decorator
    return method(self, *args, **kwargs)
  File "E:\djangoproject\virblog\virblog\lib\site-packages\django_redis\cache.py", line 83, in get
    client=client)
  File "E:\djangoproject\virblog\virblog\lib\site-packages\django_redis\client\default.py", line 209, in get
    raise ConnectionInterrupted(connection=client, parent=e)
django_redis.exceptions.ConnectionInterrupted: Redis ConnectionError: Error 10061 connecting to 127.0.0.1:6379. ”…”⁄ƒø±Íº∆À„ª˙ª˝º´æ‹æ¯£¨Œﬁ∑®¡¨Ω”°£.

During handling of the above exception, another exception occurred:

Traceback (most recent call last):
  File "E:\djangoproject\virblog\virblog\lib\site-packages\django\core\handlers\exception.py", line 39, in inner
    response = get_response(request)
  File "E:\djangoproject\virblog\virblog\lib\site-packages\django\core\handlers\base.py", line 187, in _get_response
    response = self.process_exception_by_middleware(e, request)
  File "E:\djangoproject\virblog\virblog\lib\site-packages\django\core\handlers\base.py", line 185, in _get_response
    response = wrapped_callback(request, *callback_args, **callback_kwargs)
  File "E:\djangoproject\virblog\virblog\lib\site-packages\django\utils\decorators.py", line 141, in _wrapped_view
    result = middleware.process_request(request)
  File "E:\djangoproject\virblog\virblog\lib\site-packages\django\middleware\cache.py", line 133, in process_request
    cache_key = get_cache_key(request, self.key_prefix, 'GET', cache=self.cache)
  File "E:\djangoproject\virblog\virblog\lib\site-packages\django\utils\cache.py", line 318, in get_cache_key
    headerlist = cache.get(cache_key)
  File "E:\djangoproject\virblog\virblog\lib\site-packages\django_redis\cache.py", line 41, in _decorator
    raise e.parent
  File "E:\djangoproject\virblog\virblog\lib\site-packages\django_redis\client\default.py", line 207, in get
    value = client.get(key)
  File "E:\djangoproject\virblog\virblog\lib\site-packages\redis\client.py", line 880, in get
    return self.execute_command('GET', name)
  File "E:\djangoproject\virblog\virblog\lib\site-packages\redis\client.py", line 578, in execute_command
    connection.send_command(*args)
  File "E:\djangoproject\virblog\virblog\lib\site-packages\redis\connection.py", line 563, in send_command
    self.send_packed_command(self.pack_command(*args))
  File "E:\djangoproject\virblog\virblog\lib\site-packages\redis\connection.py", line 538, in send_packed_command
    self.connect()
  File "E:\djangoproject\virblog\virblog\lib\site-packages\redis\connection.py", line 442, in connect
    raise ConnectionError(self._error_message(e))
redis.exceptions.ConnectionError: Error 10061 connecting to 127.0.0.1:6379. ”…”⁄ƒø±Íº∆À„ª˙ª˝º´æ‹æ¯£¨Œﬁ∑®¡¨Ω”°£.
ERROR 2017-07-14 16:08:34,635 exception 13108 7292 Internal Server Error: /article/1
Traceback (most recent call last):
  File "E:\djangoproject\virblog\virblog\lib\site-packages\django_redis\cache.py", line 34, in _decorator
    return method(self, *args, **kwargs)
  File "E:\djangoproject\virblog\virblog\lib\site-packages\django_redis\cache.py", line 83, in get
    client=client)
  File "E:\djangoproject\virblog\virblog\lib\site-packages\django_redis\client\default.py", line 209, in get
    raise ConnectionInterrupted(connection=client, parent=e)
django_redis.exceptions.ConnectionInterrupted: Redis ConnectionError: Error 10061 connecting to 127.0.0.1:6379. ”…”⁄ƒø±Íº∆À„ª˙ª˝º´æ‹æ¯£¨Œﬁ∑®¡¨Ω”°£.

During handling of the above exception, another exception occurred:

Traceback (most recent call last):
  File "E:\djangoproject\virblog\virblog\lib\site-packages\django\core\handlers\exception.py", line 39, in inner
    response = get_response(request)
  File "E:\djangoproject\virblog\virblog\lib\site-packages\django\core\handlers\base.py", line 187, in _get_response
    response = self.process_exception_by_middleware(e, request)
  File "E:\djangoproject\virblog\virblog\lib\site-packages\django\core\handlers\base.py", line 185, in _get_response
    response = wrapped_callback(request, *callback_args, **callback_kwargs)
  File "E:\djangoproject\virblog\virblog\lib\site-packages\django\utils\decorators.py", line 141, in _wrapped_view
    result = middleware.process_request(request)
  File "E:\djangoproject\virblog\virblog\lib\site-packages\django\middleware\cache.py", line 133, in process_request
    cache_key = get_cache_key(request, self.key_prefix, 'GET', cache=self.cache)
  File "E:\djangoproject\virblog\virblog\lib\site-packages\django\utils\cache.py", line 318, in get_cache_key
    headerlist = cache.get(cache_key)
  File "E:\djangoproject\virblog\virblog\lib\site-packages\django_redis\cache.py", line 41, in _decorator
    raise e.parent
  File "E:\djangoproject\virblog\virblog\lib\site-packages\django_redis\client\default.py", line 207, in get
    value = client.get(key)
  File "E:\djangoproject\virblog\virblog\lib\site-packages\redis\client.py", line 880, in get
    return self.execute_command('GET', name)
  File "E:\djangoproject\virblog\virblog\lib\site-packages\redis\client.py", line 578, in execute_command
    connection.send_command(*args)
  File "E:\djangoproject\virblog\virblog\lib\site-packages\redis\connection.py", line 563, in send_command
    self.send_packed_command(self.pack_command(*args))
  File "E:\djangoproject\virblog\virblog\lib\site-packages\redis\connection.py", line 538, in send_packed_command
    self.connect()
  File "E:\djangoproject\virblog\virblog\lib\site-packages\redis\connection.py", line 442, in connect
    raise ConnectionError(self._error_message(e))
redis.exceptions.ConnectionError: Error 10061 connecting to 127.0.0.1:6379. ”…”⁄ƒø±Íº∆À„ª˙ª˝º´æ‹æ¯£¨Œﬁ∑®¡¨Ω”°£.
ERROR 2017-07-14 16:08:35,439 exception 13108 13024 Internal Server Error: /article/1
Traceback (most recent call last):
  File "E:\djangoproject\virblog\virblog\lib\site-packages\django_redis\cache.py", line 34, in _decorator
    return method(self, *args, **kwargs)
  File "E:\djangoproject\virblog\virblog\lib\site-packages\django_redis\cache.py", line 83, in get
    client=client)
  File "E:\djangoproject\virblog\virblog\lib\site-packages\django_redis\client\default.py", line 209, in get
    raise ConnectionInterrupted(connection=client, parent=e)
django_redis.exceptions.ConnectionInterrupted: Redis ConnectionError: Error 10061 connecting to 127.0.0.1:6379. ”…”⁄ƒø±Íº∆À„ª˙ª˝º´æ‹æ¯£¨Œﬁ∑®¡¨Ω”°£.

During handling of the above exception, another exception occurred:

Traceback (most recent call last):
  File "E:\djangoproject\virblog\virblog\lib\site-packages\django\core\handlers\exception.py", line 39, in inner
    response = get_response(request)
  File "E:\djangoproject\virblog\virblog\lib\site-packages\django\core\handlers\base.py", line 187, in _get_response
    response = self.process_exception_by_middleware(e, request)
  File "E:\djangoproject\virblog\virblog\lib\site-packages\django\core\handlers\base.py", line 185, in _get_response
    response = wrapped_callback(request, *callback_args, **callback_kwargs)
  File "E:\djangoproject\virblog\virblog\lib\site-packages\django\utils\decorators.py", line 141, in _wrapped_view
    result = middleware.process_request(request)
  File "E:\djangoproject\virblog\virblog\lib\site-packages\django\middleware\cache.py", line 133, in process_request
    cache_key = get_cache_key(request, self.key_prefix, 'GET', cache=self.cache)
  File "E:\djangoproject\virblog\virblog\lib\site-packages\django\utils\cache.py", line 318, in get_cache_key
    headerlist = cache.get(cache_key)
  File "E:\djangoproject\virblog\virblog\lib\site-packages\django_redis\cache.py", line 41, in _decorator
    raise e.parent
  File "E:\djangoproject\virblog\virblog\lib\site-packages\django_redis\client\default.py", line 207, in get
    value = client.get(key)
  File "E:\djangoproject\virblog\virblog\lib\site-packages\redis\client.py", line 880, in get
    return self.execute_command('GET', name)
  File "E:\djangoproject\virblog\virblog\lib\site-packages\redis\client.py", line 578, in execute_command
    connection.send_command(*args)
  File "E:\djangoproject\virblog\virblog\lib\site-packages\redis\connection.py", line 563, in send_command
    self.send_packed_command(self.pack_command(*args))
  File "E:\djangoproject\virblog\virblog\lib\site-packages\redis\connection.py", line 538, in send_packed_command
    self.connect()
  File "E:\djangoproject\virblog\virblog\lib\site-packages\redis\connection.py", line 442, in connect
    raise ConnectionError(self._error_message(e))
redis.exceptions.ConnectionError: Error 10061 connecting to 127.0.0.1:6379. ”…”⁄ƒø±Íº∆À„ª˙ª˝º´æ‹æ¯£¨Œﬁ∑®¡¨Ω”°£.
ERROR 2017-07-14 16:08:41,853 exception 13108 3280 Internal Server Error: /article/1
Traceback (most recent call last):
  File "E:\djangoproject\virblog\virblog\lib\site-packages\django_redis\cache.py", line 34, in _decorator
    return method(self, *args, **kwargs)
  File "E:\djangoproject\virblog\virblog\lib\site-packages\django_redis\cache.py", line 83, in get
    client=client)
  File "E:\djangoproject\virblog\virblog\lib\site-packages\django_redis\client\default.py", line 209, in get
    raise ConnectionInterrupted(connection=client, parent=e)
django_redis.exceptions.ConnectionInterrupted: Redis ConnectionError: Error 10061 connecting to 127.0.0.1:6379. ”…”⁄ƒø±Íº∆À„ª˙ª˝º´æ‹æ¯£¨Œﬁ∑®¡¨Ω”°£.

During handling of the above exception, another exception occurred:

Traceback (most recent call last):
  File "E:\djangoproject\virblog\virblog\lib\site-packages\django\core\handlers\exception.py", line 39, in inner
    response = get_response(request)
  File "E:\djangoproject\virblog\virblog\lib\site-packages\django\core\handlers\base.py", line 187, in _get_response
    response = self.process_exception_by_middleware(e, request)
  File "E:\djangoproject\virblog\virblog\lib\site-packages\django\core\handlers\base.py", line 185, in _get_response
    response = wrapped_callback(request, *callback_args, **callback_kwargs)
  File "E:\djangoproject\virblog\virblog\lib\site-packages\django\utils\decorators.py", line 141, in _wrapped_view
    result = middleware.process_request(request)
  File "E:\djangoproject\virblog\virblog\lib\site-packages\django\middleware\cache.py", line 133, in process_request
    cache_key = get_cache_key(request, self.key_prefix, 'GET', cache=self.cache)
  File "E:\djangoproject\virblog\virblog\lib\site-packages\django\utils\cache.py", line 318, in get_cache_key
    headerlist = cache.get(cache_key)
  File "E:\djangoproject\virblog\virblog\lib\site-packages\django_redis\cache.py", line 41, in _decorator
    raise e.parent
  File "E:\djangoproject\virblog\virblog\lib\site-packages\django_redis\client\default.py", line 207, in get
    value = client.get(key)
  File "E:\djangoproject\virblog\virblog\lib\site-packages\redis\client.py", line 880, in get
    return self.execute_command('GET', name)
  File "E:\djangoproject\virblog\virblog\lib\site-packages\redis\client.py", line 578, in execute_command
    connection.send_command(*args)
  File "E:\djangoproject\virblog\virblog\lib\site-packages\redis\connection.py", line 563, in send_command
    self.send_packed_command(self.pack_command(*args))
  File "E:\djangoproject\virblog\virblog\lib\site-packages\redis\connection.py", line 538, in send_packed_command
    self.connect()
  File "E:\djangoproject\virblog\virblog\lib\site-packages\redis\connection.py", line 442, in connect
    raise ConnectionError(self._error_message(e))
redis.exceptions.ConnectionError: Error 10061 connecting to 127.0.0.1:6379. ”…”⁄ƒø±Íº∆À„ª˙ª˝º´æ‹æ¯£¨Œﬁ∑®¡¨Ω”°£.
ERROR 2017-07-14 16:08:42,533 exception 13108 14424 Internal Server Error: /article/1
Traceback (most recent call last):
  File "E:\djangoproject\virblog\virblog\lib\site-packages\django_redis\cache.py", line 34, in _decorator
    return method(self, *args, **kwargs)
  File "E:\djangoproject\virblog\virblog\lib\site-packages\django_redis\cache.py", line 83, in get
    client=client)
  File "E:\djangoproject\virblog\virblog\lib\site-packages\django_redis\client\default.py", line 209, in get
    raise ConnectionInterrupted(connection=client, parent=e)
django_redis.exceptions.ConnectionInterrupted: Redis ConnectionError: Error 10061 connecting to 127.0.0.1:6379. ”…”⁄ƒø±Íº∆À„ª˙ª˝º´æ‹æ¯£¨Œﬁ∑®¡¨Ω”°£.

During handling of the above exception, another exception occurred:

Traceback (most recent call last):
  File "E:\djangoproject\virblog\virblog\lib\site-packages\django\core\handlers\exception.py", line 39, in inner
    response = get_response(request)
  File "E:\djangoproject\virblog\virblog\lib\site-packages\django\core\handlers\base.py", line 187, in _get_response
    response = self.process_exception_by_middleware(e, request)
  File "E:\djangoproject\virblog\virblog\lib\site-packages\django\core\handlers\base.py", line 185, in _get_response
    response = wrapped_callback(request, *callback_args, **callback_kwargs)
  File "E:\djangoproject\virblog\virblog\lib\site-packages\django\utils\decorators.py", line 141, in _wrapped_view
    result = middleware.process_request(request)
  File "E:\djangoproject\virblog\virblog\lib\site-packages\django\middleware\cache.py", line 133, in process_request
    cache_key = get_cache_key(request, self.key_prefix, 'GET', cache=self.cache)
  File "E:\djangoproject\virblog\virblog\lib\site-packages\django\utils\cache.py", line 318, in get_cache_key
    headerlist = cache.get(cache_key)
  File "E:\djangoproject\virblog\virblog\lib\site-packages\django_redis\cache.py", line 41, in _decorator
    raise e.parent
  File "E:\djangoproject\virblog\virblog\lib\site-packages\django_redis\client\default.py", line 207, in get
    value = client.get(key)
  File "E:\djangoproject\virblog\virblog\lib\site-packages\redis\client.py", line 880, in get
    return self.execute_command('GET', name)
  File "E:\djangoproject\virblog\virblog\lib\site-packages\redis\client.py", line 578, in execute_command
    connection.send_command(*args)
  File "E:\djangoproject\virblog\virblog\lib\site-packages\redis\connection.py", line 563, in send_command
    self.send_packed_command(self.pack_command(*args))
  File "E:\djangoproject\virblog\virblog\lib\site-packages\redis\connection.py", line 538, in send_packed_command
    self.connect()
  File "E:\djangoproject\virblog\virblog\lib\site-packages\redis\connection.py", line 442, in connect
    raise ConnectionError(self._error_message(e))
redis.exceptions.ConnectionError: Error 10061 connecting to 127.0.0.1:6379. ”…”⁄ƒø±Íº∆À„ª˙ª˝º´æ‹æ¯£¨Œﬁ∑®¡¨Ω”°£.
ERROR 2017-07-14 16:08:42,724 exception 13108 14472 Internal Server Error: /article/1
Traceback (most recent call last):
  File "E:\djangoproject\virblog\virblog\lib\site-packages\django_redis\cache.py", line 34, in _decorator
    return method(self, *args, **kwargs)
  File "E:\djangoproject\virblog\virblog\lib\site-packages\django_redis\cache.py", line 83, in get
    client=client)
  File "E:\djangoproject\virblog\virblog\lib\site-packages\django_redis\client\default.py", line 209, in get
    raise ConnectionInterrupted(connection=client, parent=e)
django_redis.exceptions.ConnectionInterrupted: Redis ConnectionError: Error 10061 connecting to 127.0.0.1:6379. ”…”⁄ƒø±Íº∆À„ª˙ª˝º´æ‹æ¯£¨Œﬁ∑®¡¨Ω”°£.

During handling of the above exception, another exception occurred:

Traceback (most recent call last):
  File "E:\djangoproject\virblog\virblog\lib\site-packages\django\core\handlers\exception.py", line 39, in inner
    response = get_response(request)
  File "E:\djangoproject\virblog\virblog\lib\site-packages\django\core\handlers\base.py", line 187, in _get_response
    response = self.process_exception_by_middleware(e, request)
  File "E:\djangoproject\virblog\virblog\lib\site-packages\django\core\handlers\base.py", line 185, in _get_response
    response = wrapped_callback(request, *callback_args, **callback_kwargs)
  File "E:\djangoproject\virblog\virblog\lib\site-packages\django\utils\decorators.py", line 141, in _wrapped_view
    result = middleware.process_request(request)
  File "E:\djangoproject\virblog\virblog\lib\site-packages\django\middleware\cache.py", line 133, in process_request
    cache_key = get_cache_key(request, self.key_prefix, 'GET', cache=self.cache)
  File "E:\djangoproject\virblog\virblog\lib\site-packages\django\utils\cache.py", line 318, in get_cache_key
    headerlist = cache.get(cache_key)
  File "E:\djangoproject\virblog\virblog\lib\site-packages\django_redis\cache.py", line 41, in _decorator
    raise e.parent
  File "E:\djangoproject\virblog\virblog\lib\site-packages\django_redis\client\default.py", line 207, in get
    value = client.get(key)
  File "E:\djangoproject\virblog\virblog\lib\site-packages\redis\client.py", line 880, in get
    return self.execute_command('GET', name)
  File "E:\djangoproject\virblog\virblog\lib\site-packages\redis\client.py", line 578, in execute_command
    connection.send_command(*args)
  File "E:\djangoproject\virblog\virblog\lib\site-packages\redis\connection.py", line 563, in send_command
    self.send_packed_command(self.pack_command(*args))
  File "E:\djangoproject\virblog\virblog\lib\site-packages\redis\connection.py", line 538, in send_packed_command
    self.connect()
  File "E:\djangoproject\virblog\virblog\lib\site-packages\redis\connection.py", line 442, in connect
    raise ConnectionError(self._error_message(e))
redis.exceptions.ConnectionError: Error 10061 connecting to 127.0.0.1:6379. ”…”⁄ƒø±Íº∆À„ª˙ª˝º´æ‹æ¯£¨Œﬁ∑®¡¨Ω”°£.
ERROR 2017-07-14 16:08:42,917 exception 13108 11044 Internal Server Error: /article/1
Traceback (most recent call last):
  File "E:\djangoproject\virblog\virblog\lib\site-packages\django_redis\cache.py", line 34, in _decorator
    return method(self, *args, **kwargs)
  File "E:\djangoproject\virblog\virblog\lib\site-packages\django_redis\cache.py", line 83, in get
    client=client)
  File "E:\djangoproject\virblog\virblog\lib\site-packages\django_redis\client\default.py", line 209, in get
    raise ConnectionInterrupted(connection=client, parent=e)
django_redis.exceptions.ConnectionInterrupted: Redis ConnectionError: Error 10061 connecting to 127.0.0.1:6379. ”…”⁄ƒø±Íº∆À„ª˙ª˝º´æ‹æ¯£¨Œﬁ∑®¡¨Ω”°£.

During handling of the above exception, another exception occurred:

Traceback (most recent call last):
  File "E:\djangoproject\virblog\virblog\lib\site-packages\django\core\handlers\exception.py", line 39, in inner
    response = get_response(request)
  File "E:\djangoproject\virblog\virblog\lib\site-packages\django\core\handlers\base.py", line 187, in _get_response
    response = self.process_exception_by_middleware(e, request)
  File "E:\djangoproject\virblog\virblog\lib\site-packages\django\core\handlers\base.py", line 185, in _get_response
    response = wrapped_callback(request, *callback_args, **callback_kwargs)
  File "E:\djangoproject\virblog\virblog\lib\site-packages\django\utils\decorators.py", line 141, in _wrapped_view
    result = middleware.process_request(request)
  File "E:\djangoproject\virblog\virblog\lib\site-packages\django\middleware\cache.py", line 133, in process_request
    cache_key = get_cache_key(request, self.key_prefix, 'GET', cache=self.cache)
  File "E:\djangoproject\virblog\virblog\lib\site-packages\django\utils\cache.py", line 318, in get_cache_key
    headerlist = cache.get(cache_key)
  File "E:\djangoproject\virblog\virblog\lib\site-packages\django_redis\cache.py", line 41, in _decorator
    raise e.parent
  File "E:\djangoproject\virblog\virblog\lib\site-packages\django_redis\client\default.py", line 207, in get
    value = client.get(key)
  File "E:\djangoproject\virblog\virblog\lib\site-packages\redis\client.py", line 880, in get
    return self.execute_command('GET', name)
  File "E:\djangoproject\virblog\virblog\lib\site-packages\redis\client.py", line 578, in execute_command
    connection.send_command(*args)
  File "E:\djangoproject\virblog\virblog\lib\site-packages\redis\connection.py", line 563, in send_command
    self.send_packed_command(self.pack_command(*args))
  File "E:\djangoproject\virblog\virblog\lib\site-packages\redis\connection.py", line 538, in send_packed_command
    self.connect()
  File "E:\djangoproject\virblog\virblog\lib\site-packages\redis\connection.py", line 442, in connect
    raise ConnectionError(self._error_message(e))
redis.exceptions.ConnectionError: Error 10061 connecting to 127.0.0.1:6379. ”…”⁄ƒø±Íº∆À„ª˙ª˝º´æ‹æ¯£¨Œﬁ∑®¡¨Ω”°£.
ERROR 2017-07-14 16:09:35,236 exception 13108 3820 Internal Server Error: /article/1
Traceback (most recent call last):
  File "E:\djangoproject\virblog\virblog\lib\site-packages\django_redis\cache.py", line 34, in _decorator
    return method(self, *args, **kwargs)
  File "E:\djangoproject\virblog\virblog\lib\site-packages\django_redis\cache.py", line 83, in get
    client=client)
  File "E:\djangoproject\virblog\virblog\lib\site-packages\django_redis\client\default.py", line 209, in get
    raise ConnectionInterrupted(connection=client, parent=e)
django_redis.exceptions.ConnectionInterrupted: Redis ConnectionError: Error 10061 connecting to 127.0.0.1:6379. ”…”⁄ƒø±Íº∆À„ª˙ª˝º´æ‹æ¯£¨Œﬁ∑®¡¨Ω”°£.

During handling of the above exception, another exception occurred:

Traceback (most recent call last):
  File "E:\djangoproject\virblog\virblog\lib\site-packages\django\core\handlers\exception.py", line 39, in inner
    response = get_response(request)
  File "E:\djangoproject\virblog\virblog\lib\site-packages\django\core\handlers\base.py", line 187, in _get_response
    response = self.process_exception_by_middleware(e, request)
  File "E:\djangoproject\virblog\virblog\lib\site-packages\django\core\handlers\base.py", line 185, in _get_response
    response = wrapped_callback(request, *callback_args, **callback_kwargs)
  File "E:\djangoproject\virblog\virblog\lib\site-packages\django\utils\decorators.py", line 141, in _wrapped_view
    result = middleware.process_request(request)
  File "E:\djangoproject\virblog\virblog\lib\site-packages\django\middleware\cache.py", line 133, in process_request
    cache_key = get_cache_key(request, self.key_prefix, 'GET', cache=self.cache)
  File "E:\djangoproject\virblog\virblog\lib\site-packages\django\utils\cache.py", line 318, in get_cache_key
    headerlist = cache.get(cache_key)
  File "E:\djangoproject\virblog\virblog\lib\site-packages\django_redis\cache.py", line 41, in _decorator
    raise e.parent
  File "E:\djangoproject\virblog\virblog\lib\site-packages\django_redis\client\default.py", line 207, in get
    value = client.get(key)
  File "E:\djangoproject\virblog\virblog\lib\site-packages\redis\client.py", line 880, in get
    return self.execute_command('GET', name)
  File "E:\djangoproject\virblog\virblog\lib\site-packages\redis\client.py", line 578, in execute_command
    connection.send_command(*args)
  File "E:\djangoproject\virblog\virblog\lib\site-packages\redis\connection.py", line 563, in send_command
    self.send_packed_command(self.pack_command(*args))
  File "E:\djangoproject\virblog\virblog\lib\site-packages\redis\connection.py", line 538, in send_packed_command
    self.connect()
  File "E:\djangoproject\virblog\virblog\lib\site-packages\redis\connection.py", line 442, in connect
    raise ConnectionError(self._error_message(e))
redis.exceptions.ConnectionError: Error 10061 connecting to 127.0.0.1:6379. ”…”⁄ƒø±Íº∆À„ª˙ª˝º´æ‹æ¯£¨Œﬁ∑®¡¨Ω”°£.
